Workbook

Sheet 01_功能单位与情景
A1: 01_功能单位与情景
A3: 功能单位定义
A4: 功能单位描述 | B4: 1000张A4双面四色宣传单（157g铜版纸，单页，成品质量要求一致）
A5: 功能单位数量 | B5: 1000 | C5: 张
A7: 情景定义
A8: 场景编号 | B8: 场景名称 | C8: 工艺类型 | D8: 产量(张) | E8: 批次特征 | F8: 备注
A9: S1 | B9: 小批量印刷 | C9: 数字印刷 | D9: 1000 | E9: 短版、个性化 | F9: 本MVP目标
A10: S1 | B10: 小批量印刷 | C10: 胶印 | D10: 1000 | E10: 传统制版印刷 | F10: 对比基准
A12: 控制项（用于敏感性分析）
A13: 纸张因子选择（主线/中国） | B13: 主线 | C13: 填“主线”=使用B7(1.29)；填“中国”=使用B8(1.49)
A14: 电耗数据来源（估算/实测） | B14: 估算 | C14: 填“估算”使用占位值；填“实测/手册”优先使用实测/手册值（若未填则回退占位）

Sheet 02_活动数据输入
A1: 02_活动数据输入
A3: 场景S1 - 活动数据清单
A5: 场景编号 | B5: 工艺类型 | C5: 产量(张) | D5: 纸张消耗(kg) | E5: 电耗(kWh) | F5: 油墨/墨粉(kg) | G5: 版材消耗(张) | H5: 废品率 | I5: 数据来源 | J5: 备注
A6: S1 | B6: 数字印刷 | C6: 1000 | D6: 9.89 | E6: =IF('01_功能单位与情景'!$B$14="实测/手册",IF(ISNUMBER($C$16),$C$16,$C$14),$C$14) -> 6.13 | F6: 待补/需人工核验 | G6: 0 | H6: 0.01 | I6: 文献换算（VTT 2010） | J6: 文献区间换算：电摄影印刷能耗 590–650 kWh/tonne；按纸张消耗9.89 kg/1000张折算 => 6.13 kWh/1000张（中值）。
A7: S1 | B7: 胶印 | C7: 1000 | D7: 10.58 | E7: =IF('01_功能单位与情景'!$B$14="实测/手册",IF(ISNUMBER($C$17),$C$17,$C$15),$C$15) -> 9.73 | F7: 待补/需人工核验 | G7: 待补/需人工核验 | H7: 0.08 | I7: 文献换算（VTT 2010） | J7: 文献区间换算：平张胶印能耗 800–1040 kWh/tonne；按纸张消耗10.58 kg/1000张折算 => 9.73 kWh/1000张（中值）。
A9: 计算说明：
A10: 1. 纸张消耗 = 产量 × 单张克重 × (1 + 废品率)
A11: 2. 实际产量 = 订单量 / (1 - 废品率)
A13: 电耗数据（kWh/1000张）
B14: 数字印刷_文献换算（VTT 2010 Table 4，Electrophotography） | C14: 6.13
B15: 胶印_文献换算（VTT 2010 Table 4，Sheetfed offset） | C15: 9.73
B16: 数字印刷_实测/手册 | C16: 待补/需人工核验
B17: 胶印_实测/手册 | C17: 待补/需人工核验

Sheet 03_排放因子库
A1: 03_排放因子库
A3: 排放因子清单
A4: 纸张排放因子_当前（自动） | B4: =IF('01_功能单位与情景'!B13="中国",B8,B7) -> 1.29 | C4: kgCO2e/kg | D4: 自动选择（主线/中国） | F4: 用于纸张项 | G4: 切换01表B13即可做敏感性（不改其他公式）
A5: 因子名称 | B5: 因子值 | C5: 单位 | D5: 来源 | E5: 年份 | F5: 适用范围 | G5: 备注
A6: 电力排放因子 | B6: 0.5777 | C6: kgCO2e/kWh | D6: 生态环境部等《公告2025年第19号》附件（2024年全国电力平均碳足迹因子） | E6: 2024 | F6: 中国电网平均
A7: 纸张排放因子 | B7: 1.29 | C7: kgCO2e/kg | D7: 待核验：当前使用值1.29（需补充权威cradle-to-gate来源；作为基线值保留） | E7: v3.10 | F7: 欧洲RER / 全球参考 | G7: 主线值：国际通用基准，置信度极高；敏感性分析备选值：1.49(APP中国)
A8: 纸张排放因子_中国备选 | B8: 1.49 | C8: kgCO2e/kg | D8: 待核验：当前使用值1.49（需补充权威中国情境来源；仅用于敏感性） | E8: 2007-2009 | F8: 中国本土化 | G8: 敏感性分析备选值，反映中国高煤电占比能源结构
A9: 数字印刷墨粉排放因子 | B9: 待补/需人工核验 | C9: kgCO2e/kg | G9: 对应04_计算过程!F8（数字印刷墨粉）
A10: 胶印油墨排放因子 | B10: 待补/需人工核验 | C10: kgCO2e/kg | G10: 对应04_计算过程!F13（胶印油墨）
A11: 胶印版材排放因子 | B11: 待补/需人工核验 | C11: kgCO2e/张 | G11: 对应04_计算过程!F14（胶印版材）
A12: 数字印刷设备制造排放（寿命分摊，预留） | B12: 待补/非当前阶段 | C12: kgCO2e/台 | G12: 非S1 MVP必需
A13: 胶印设备制造排放（寿命分摊，预留） | B13: 待补/非当前阶段 | C13: kgCO2e/台 | G13: 非S1 MVP必需
A14: 纸张排放因子_Two Sides（Coated Free/CWF） | B14: ='08_纸张因子证据'!E13 -> 1.6192953 | C14: kgCO2e/kg | D14: Two Sides North America《Printing & Writing Papers LCA Summary Report》Coated Free=1469 kgCO2eq/short ton，折算=1.619
A15: 1. 电力因子采用生态环境部最新发布值
A16: 2. 其他因子优先采用Ecoinvent数据库，其次文献

Sheet 04_计算过程
A1: 04_计算过程
A3: 碳足迹计算明细（公式追踪）
A5: 场景 | B5: 工艺 | C5: 排放源 | D5: 活动数据 | E5: × | F5: 排放因子 | G5: = | H5: 排放量(kgCO2e) | I5: 占比 | J5: 数据来源 | K5: 备注
A6: S1 | B6: 数字印刷 | C6: 纸张 | D6: ='02_活动数据输入'!D6 -> 9.89 | E6: × | F6: ='03_排放因子库'!B4 -> 1.29 | G6: =H6*J6 | H6: =IFERROR(D6*F6,0) -> 12.7581
A7: S1 | B7: 数字印刷 | C7: 电力 | D7: ='02_活动数据输入'!E6 -> 6.13 | E7: × | F7: ='03_排放因子库'!B6 -> 0.5777 | G7: =H7*J7 | H7: =IFERROR(D7*F7,0) -> 3.541301
A8: S1 | B8: 数字印刷 | C8: 墨粉 | D8: ='02_活动数据输入'!F6 -> 待补/需人工核验 | E8: × | F8: ='03_排放因子库'!B9 -> 待补/需人工核验 | G8: =H8*J8 | H8: =IFERROR(D8*F8,0) -> 0
A9: S1 | B9: 数字印刷 | C9: 版材 | D9: 0 | E9: × | F9: 0 | G9: = | H9: =IFERROR(D9*F9,0) -> 0 | I9: 0% | J9: 免版材
A11: S1 | B11: 胶印 | C11: 纸张 | D11: ='02_活动数据输入'!D7 -> 10.58 | E11: × | F11: ='03_排放因子库'!B4 -> 1.29 | G11: =H11*J11 | H11: =IFERROR(D11*F11,0) -> 13.6482
A12: S1 | B12: 胶印 | C12: 电力 | D12: ='02_活动数据输入'!E7 -> 9.73 | E12: × | F12: ='03_排放因子库'!B6 -> 0.5777 | G12: =H12*J12 | H12: =IFERROR(D12*F12,0) -> 5.621021
A13: S1 | B13: 胶印 | C13: 油墨 | D13: ='02_活动数据输入'!F7 -> 待补/需人工核验 | E13: × | F13: ='03_排放因子库'!B10 -> 待补/需人工核验 | G13: =H13*J13 | H13: =IFERROR(D13*F13,0) -> 0
A14: S1 | B14: 胶印 | C14: 版材 | D14: ='02_活动数据输入'!G7 -> 待补/需人工核验 | E14: × | F14: ='03_排放因子库'!B11 -> 待补/需人工核验 | G14: =H14*J14 | H14: =IFERROR(D14*F14,0) -> 0
A16: 计算逻辑说明：
A17: 1. 排放量 = 活动数据 × 排放因子
A18: 2. 纸张活动数据已含废品率调整
A19: 3. 所有公式引用上游sheet，可追踪

Sheet 05_结果汇总
A1: 05_结果汇总
A3: 场景S1 碳足迹对比结果
A5: 场景编号 | B5: 工艺类型 | C5: 功能单位 | D5: 碳足迹(kgCO2e) | E5: 单位碳足迹(gCO2e/张) | F5: 主要排放源 | G5: 数据来源 | H5: 备注
A6: S1 | B6: 数字印刷 | C6: 1000张A4 | D6: =SUM('04_计算过程'!H6:H9) -> 16.299401 | E6: =D6 -> 16.299401 | F6: 电力/纸张 | G6: V2-纸张+电力（电耗占位可替换） | H6: 电耗为文献区间折算占位（VTT Table 4→kWh/1000张）；纸张+电力V2；缺失项按0并在正文披露。
A7: S1 | B7: 胶印 | C7: 1000张A4 | D7: =SUM('04_计算过程'!H11:H14) -> 19.269221 | E7: =D7 -> 19.269221 | F7: 纸张/电力/版材 | G7: V2-纸张+电力（电耗占位可替换） | H7: 电耗为文献区间折算占位（VTT Table 4→kWh/1000张）；纸张+电力V2；缺失项按0并在正文披露。
A9: 对比结论（待数据补全后生成） | B9: 对比结论（基于当前活动数据与因子；缺失项未纳入）
A11: 指标 | B11: 数字印刷 | C11: 胶印 | D11: 差值 | E11: 结论
A12: 单位碳足迹(gCO2e/张) | B12: =E6 | C12: =E7 | D12: =B12-C12 | E12: =IF(D12<0,"数字印刷更低",IF(D12>0,"胶印更低","相同")) -> 胶印更低
A13: 总碳足迹(kgCO2e) | B13: =D6 | C13: =D7 | D13: =B13-C13 | E13: =IF(D13<0,"数字印刷更低",IF(D13>0,"胶印更低","相同")) -> 胶印更低
A15: 注：当前结果为公式框架，需补全活动数据后计算得出实际数值

Sheet 06_数据来源留痕
A1: 06_数据来源留痕
A3: 数据项 | B3: 数值/状态 | C3: 来源类型 | D3: 具体来源 | E3: 获取日期 | F3: 可信度 | G3: 备注
A4: 功能单位定义 | B4: 1000张A4 | C4: 标准 | D4: ISO 16759 | E4: 2026-02-23 | F4: 高 | G4: 已锁定
A5: 电力排放因子 | B5: 0.5777 | C5: 官方 | D5: 生态环境部等《公告2025年第19号》附件PDF《2024年全国电力碳足迹因子》（全国平均0.5777 kgCO2e/kWh） | E5: 2026-02-27 | F5: 高 | G5: 已锁定
A6: 数字印刷-纸张消耗 | B6: 待补 | G6: 需实测或文献
A7: 数字印刷-电耗 | B7: 6.13 | C7: 文献区间+折算（按吨→按功能单位） | D7: VTT Research Notes 2560 (Pihkola et al., 2010) Table 4: electrophotography energy consumption 590–650 kWh/tonne printed products; converted using FU paper mass. | E7: 2026-02-26 | F7: 中（公开手册+折算；建议实测替换） | G7: 需设备参数
A8: 数字印刷-墨粉消耗 | B8: 待补 | G8: 需实测
A9: 胶印-纸张消耗 | B9: 待补 | G9: 需实测或文献
A10: 胶印-电耗 | B10: 9.73 | C10: 文献区间+折算（按吨→按功能单位） | D10: VTT Research Notes 2560 (Pihkola et al., 2010) Table 4: sheetfed offset energy consumption 800–1040 kWh/tonne printed products; converted using FU paper mass. | E10: 2026-02-26 | F10: 中（文献汇总/范围；建议用设备手册或实测替换） | G10: 需设备参数
A11: 胶印-油墨消耗 | B11: 待补 | G11: 需实测
A12: 胶印-版材消耗 | B12: 待补 | G12: 需实测
A13: 纸张排放因子 | B13: 待补 | G13: 需数据库/文献
A14: 油墨/墨粉排放因子 | B14: 待补 | G14: 需数据库/文献
A15: 版材排放因子 | B15: 待补 | G15: 需数据库/文献
A16: 电力CO2因子（区域/省级） | B16: 见07_敏感性分析 | C16: 官方 | D16: 生态环境部、国家统计局《公告2025年第47号》附件PDF《2023年电力二氧化碳排放因子》（全国/区域/省级，kgCO2/kWh） | E16: 2026-02-27

Sheet 07_敏感性分析
A1: 07_敏感性分析（模板）
A3: 输入（自动引用主模型）
A4: 数字印刷电耗(kWh/1000张) | B4: ='02_活动数据输入'!E6 -> 6.13
A5: 胶印电耗(kWh/1000张) | B5: ='02_活动数据输入'!E7 -> 9.73
A6: 数字印刷纸张消耗(kg/1000张) | B6: ='02_活动数据输入'!D6 -> 9.89
A7: 胶印纸张消耗(kg/1000张) | B7: ='02_活动数据输入'!D7 -> 10.58
A9: 纸张因子（主线 vs 中国备选）
A10: 纸张因子_主线 | B10: ='03_排放因子库'!B7 -> 1.29
A11: 纸张因子_中国备选 | B11: ='03_排放因子库'!B8 -> 1.49
A12: 纸张因子_Two Sides(CWF) | B12: ='03_排放因子库'!B14 -> 1.6192953
A13: 电力因子（主线CFP + CO2口径敏感性）
A14: CFP全国电力平均碳足迹因子(2024, kgCO2e/kWh) | B14: ='03_排放因子库'!B6 -> 0.5777 | D14: 区域(用于CO2敏感性) | E14: 因子(kgCO2/kWh)
A15: CO2全国电力平均排放因子(2023, kgCO2/kWh) | B15: 0.5306 | D15: 华北 | E15: 0.6361
D16: 东北 | E16: 0.5122
A17: CO2区域选择 | B17: 华东 | D17: 华东 | E17: 0.55
A18: CO2区域因子(kgCO2/kWh) | B18: =IFERROR(VLOOKUP($B$17,$D$15:$E$21,2,FALSE),"待补") -> 0.55 | D18: 华中 | E18: 0.5271
D19: 西北 | E19: 0.5543
A20: CO2省级选择 | B20: 四川 | D20: 南方 | E20: 0.4042
A21: CO2省级因子(kgCO2/kWh) | B21: =IFERROR(VLOOKUP($B$20,$D$25:$E$54,2,FALSE),"待补") -> 0.1564 | D21: 西南 | E21: 0.2472
D23: 省份(用于CO2敏感性) | E23: 因子(kgCO2/kWh)
D25: 北京 | E25: 0.5554
D26: 天津 | E26: 0.6796
D27: 河北 | E27: 0.6516
D28: 山西 | E28: 0.6634
D29: 内蒙古 | E29: 0.6479
D30: 辽宁 | E30: 0.4878
D31: 吉林 | E31: 0.4671
D32: 黑龙江 | E32: 0.5229
D33: 上海 | E33: 0.5737
D34: 江苏 | E34: 0.5827
D35: 浙江 | E35: 0.4974
A36: 电耗文献区间（VTT 2010 Table 4，kWh/tonne） | D36: 安徽 | E36: 0.6553
A37: 数字印刷（电摄影）kWh/tonne | B37: 590–650 | D37: 福建 | E37: 0.4211
A38: 胶印（平张胶印）kWh/tonne | B38: 800–1040 | D38: 江西 | E38: 0.5836
D39: 山东 | E39: 0.6191
A40: 按功能单位折算（中值）kWh/1000张 | D40: 河南 | E40: 0.5897
A41: 数字印刷（中值） | B41: 6.13 | D41: 湖北 | E41: 0.4044
A42: 胶印（中值） | B42: 9.73 | D42: 湖南 | E42: 0.4976
D43: 广东 | E43: 0.4419
D44: 广西 | E44: 0.4476
...

Sheet 08_纸张因子证据
A1: 纸张排放因子证据与换算（用于157g铜版纸/涂布印刷纸）
A3: 说明：
A4: - 边界：优先使用 cradle-to-gate / A1-A3（上游材料）口径；若来源为仅能源/仅CO2，则必须标注。 - 本表不强制改动主线口径；用于把Gemini调研结论落到可追溯证据与可复算换算。
A8: 证据源1：Two Sides North America（Cradle-to-Gate industry average, per bone-dry short ton）
A9: https://twosidesna.org/wp-content/uploads/sites/16/2018/05/Printing_and_Writing_Papers_-_Life-Cycle_Assessment_Summary_Report.pdf
A11: 纸种（报告分类） | B11: GWP（kg CO2 eq / bone-dry short ton） | C11: 换算 | D11: 短吨(kg) | E11: 折算后因子(kgCO2e/kg) | F11: 备注 | G11: 适用映射
A12: Uncoated Free | B12: 1194 | C12: GWP/short_ton_kg | D12: 907.18474 | E12: =B12/D12 -> 1.3161597 | F12: 报告给出cradle-to-gate industry average | G12: 对照：非涂布自由纸
A13: Coated Free | B13: 1469 | C13: GWP/short_ton_kg | D13: 907.18474 | E13: =B13/D13 -> 1.6192953 | F13: 报告给出cradle-to-gate industry average | G13: 近似：涂布不含磨木浆纸(CWF)/铜版纸
A14: Uncoated Mechanical | B14: 1176 | C14: GWP/short_ton_kg | D14: 907.18474 | E14: =B14/D14 -> 1.2963181 | G14: 对照：非涂布机械纸
A15: Coated Mechanical | B15: 1393 | C15: GWP/short_ton_kg | D15: 907.18474 | E15: =B15/D15 -> 1.5355197 | G15: 对照：涂布机械纸
A17: 推荐候选（对应铜版纸/CWF）：Coated Free 折算因子 | E17: =E13 -> 1.6192953
A19: 证据源2：BioResources (Tomberlin et al., 2020)（US 252 mills, cradle-to-gate）
A20: https://bioresources.cnr.ncsu.edu/wp-content/uploads/2020/04/BioRes_15_2_3899_Tomberlin_VY_Life_Cycle_C_Footprint_Pulp_Paper_Grades_US_Prodn_16450.pdf
A22: 指标 | B22: 原文数值（kg CO2eq / metric ton） | C22: 折算后因子(kgCO2e/kg) | D22: 适用范围 | E22: 备注
A23: 生产加权平均（跨纸种） | B23: 942 | C23: =B23/1000 -> 0.942 | D23: US总体（跨纸种） | E23: 用于量级对照；非专指涂布纸
A24: 纸种间范围（最小-最大） | B24: 608–1978 | C24: 0.608–1.978（由metric ton换算） | D24: US总体（跨纸种） | E24: 原文给出范围
A26: 证据源3：Vos & Newell (2009)（CO2 only，embedded energy in manufacturing, per finished metric ton）
A27: https://urbansustainability.seas.umich.edu/wp-content/uploads/2014/08/2009_Vos-and-Newell_A-Comparative-Analysis-of-Carbon-Dioxide-Emissions-in-Coated-Paper-Production.pdf
A29: 供应链/地区 | B29: 原文数值（kg CO2 / FMT） | C29: 折算后(kgCO2/kg) | D29: 口径限制 | E29: 备注
A30: U.S. (NewPage) | B30: 1432 | C30: =B30/1000 -> 1.432 | D30: 仅CO2；仅制造嵌入能源；不含化学品/涂料等 | E30: 可用于‘中国 vs 美国’能碳强度差异论证
A31: China industry | B31: 2478 | C31: =B31/1000 -> 2.478 | D31: 同上 | E31: 历史研究（2009），需注明时效性
A34: 将纸张因子应用到本研究功能单位（仅纸张项，kgCO2e/1000张）
A36: 工艺 | B36: 纸张消耗(kg/1000张) | C36: 使用因子（1.29）纸张排放 | D36: 使用因子（1.49）纸张排放 | E36: 使用因子（TwoSides CWF 1.619）纸张排放 | F36: 备注
A37: 数字印刷 | B37: ='02_活动数据输入'!D6 -> 9.89 | C37: =B37*'03_排放因子库'!$B$7 -> 12.7581 | D37: =B37*'03_排放因子库'!$B$8 -> 14.7361 | E37: =B37*E13 -> 16.014831 | F37: TwoSides=Coated Free(涂布自由纸)因子
A38: 胶印 | B38: ='02_活动数据输入'!D7 -> 10.58 | C38: =B38*'03_排放因子库'!$B$7 -> 13.6482 | D38: =B38*'03_排放因子库'!$B$8 -> 15.7642 | E38: =B38*E13 -> 17.132144 | F38: TwoSides=Coated Free(涂布自由纸)因子

Sheet META
A1: MASTER版本 | B1: MASTER_r13
A2: 基于 | B2: 碳足迹核算模型_MASTER_r10.xlsx
A3: 变更 | B3: 正文推进：对齐第4章r12阈值表达；在07_敏感性分析新增阈值计算区（纸张因子1.29/1.49/1.619）；其余口径不变。
